/home/g0017139/UMCG_Thesis/Working_Code/Gridsearch/Main.py:225: TqdmWarning: Iterable length 7200 > 1000 but `chunksize` is not set. This may seriously degrade multiprocess performance. Set `chunksize=1` or more.
  self.scores = process_map(self.fit, combinations, max_workers=MAX)
cpu count:
28
used: 24
  0%|          | 0/7200 [00:00<?, ?it/s]Exception in thread Thread-1:
Traceback (most recent call last):
  0%|          | 0/7200 [03:50<?, ?it/s]
  File "/data/g0017139/.envs/ClusterEnv/lib/python3.9/threading.py", line 973, in _bootstrap_inner
    self.run()
  File "/data/g0017139/.envs/ClusterEnv/lib/python3.9/concurrent/futures/process.py", line 320, in run
    self.terminate_broken(cause)
  File "/data/g0017139/.envs/ClusterEnv/lib/python3.9/concurrent/futures/process.py", line 455, in terminate_broken
    work_item.future.set_exception(bpe)
  File "/data/g0017139/.envs/ClusterEnv/lib/python3.9/concurrent/futures/_base.py", line 548, in set_exception
    raise InvalidStateError('{}: {!r}'.format(self._state, self))
concurrent.futures._base.InvalidStateError: CANCELLED: <Future at 0x7efcef88ce20 state=cancelled>
Traceback (most recent call last):
  File "/home/g0017139/UMCG_Thesis/Working_Code/Gridsearch/Main.py", line 283, in <module>
    result = search.start()
  File "/home/g0017139/UMCG_Thesis/Working_Code/Gridsearch/Main.py", line 225, in start
    self.scores = process_map(self.fit, combinations, max_workers=MAX)
  File "/data/g0017139/.envs/ClusterEnv/lib/python3.9/site-packages/tqdm/contrib/concurrent.py", line 130, in process_map
    return _executor_map(ProcessPoolExecutor, fn, *iterables, **tqdm_kwargs)
  File "/data/g0017139/.envs/ClusterEnv/lib/python3.9/site-packages/tqdm/contrib/concurrent.py", line 76, in _executor_map
    return list(tqdm_class(ex.map(fn, *iterables, **map_args), **kwargs))
  File "/data/g0017139/.envs/ClusterEnv/lib/python3.9/site-packages/tqdm/std.py", line 1180, in __iter__
    for obj in iterable:
  File "/data/g0017139/.envs/ClusterEnv/lib/python3.9/concurrent/futures/process.py", line 559, in _chain_from_iterable_of_lists
    for element in iterable:
  File "/data/g0017139/.envs/ClusterEnv/lib/python3.9/concurrent/futures/_base.py", line 608, in result_iterator
    yield fs.pop().result()
  File "/data/g0017139/.envs/ClusterEnv/lib/python3.9/concurrent/futures/_base.py", line 445, in result
    return self.__get_result()
  File "/data/g0017139/.envs/ClusterEnv/lib/python3.9/concurrent/futures/_base.py", line 390, in __get_result
    raise self._exception
concurrent.futures.process.BrokenProcessPool: A process in the process pool was terminated abruptly while the future was running or pending.
