cpu count:
28
used: 24
  0%|          | 0/112 [00:00<?, ?it/s]  1%|          | 1/112 [03:14<5:59:11, 194.16s/it]  2%|▏         | 2/112 [03:57<3:13:18, 105.44s/it]  3%|▎         | 3/112 [04:30<2:11:16, 72.26s/it]   4%|▎         | 4/112 [06:35<2:47:59, 93.33s/it]  4%|▍         | 5/112 [07:10<2:08:52, 72.27s/it]  7%|▋         | 8/112 [08:16<1:12:11, 41.65s/it]  8%|▊         | 9/112 [09:13<1:17:36, 45.21s/it]  9%|▉         | 10/112 [11:17<1:49:01, 64.13s/it] 10%|▉         | 11/112 [11:17<1:20:18, 47.71s/it] 12%|█▏        | 13/112 [11:26<48:26, 29.36s/it]   13%|█▎        | 15/112 [13:15<1:02:44, 38.80s/it] 14%|█▍        | 16/112 [13:51<1:01:19, 38.33s/it] 16%|█▌        | 18/112 [13:51<37:29, 23.93s/it]   17%|█▋        | 19/112 [15:31<1:01:57, 39.97s/it] 18%|█▊        | 20/112 [16:42<1:12:27, 47.26s/it] 19%|█▉        | 21/112 [16:43<54:07, 35.69s/it]  Exception in thread Thread-1:
 21%|██        | 23/112 [17:42<1:08:32, 46.21s/it]Traceback (most recent call last):

  File "/data/g0017139/.envs/ClusterEnv/lib/python3.9/threading.py", line 973, in _bootstrap_inner
    self.run()
  File "/data/g0017139/.envs/ClusterEnv/lib/python3.9/concurrent/futures/process.py", line 320, in run
    self.terminate_broken(cause)
  File "/data/g0017139/.envs/ClusterEnv/lib/python3.9/concurrent/futures/process.py", line 455, in terminate_broken
    work_item.future.set_exception(bpe)
  File "/data/g0017139/.envs/ClusterEnv/lib/python3.9/concurrent/futures/_base.py", line 548, in set_exception
    raise InvalidStateError('{}: {!r}'.format(self._state, self))
concurrent.futures._base.InvalidStateError: CANCELLED: <Future at 0x7f147b4300d0 state=cancelled>
Traceback (most recent call last):
  File "/home/g0017139/UMCG_Thesis/Working_Code/Gridsearch/Main.py", line 283, in <module>
    result = search.start()
  File "/home/g0017139/UMCG_Thesis/Working_Code/Gridsearch/Main.py", line 225, in start
    self.scores = process_map(self.fit, combinations, max_workers=MAX)
  File "/data/g0017139/.envs/ClusterEnv/lib/python3.9/site-packages/tqdm/contrib/concurrent.py", line 130, in process_map
    return _executor_map(ProcessPoolExecutor, fn, *iterables, **tqdm_kwargs)
  File "/data/g0017139/.envs/ClusterEnv/lib/python3.9/site-packages/tqdm/contrib/concurrent.py", line 76, in _executor_map
    return list(tqdm_class(ex.map(fn, *iterables, **map_args), **kwargs))
  File "/data/g0017139/.envs/ClusterEnv/lib/python3.9/site-packages/tqdm/std.py", line 1180, in __iter__
    for obj in iterable:
  File "/data/g0017139/.envs/ClusterEnv/lib/python3.9/concurrent/futures/process.py", line 559, in _chain_from_iterable_of_lists
    for element in iterable:
  File "/data/g0017139/.envs/ClusterEnv/lib/python3.9/concurrent/futures/_base.py", line 608, in result_iterator
    yield fs.pop().result()
  File "/data/g0017139/.envs/ClusterEnv/lib/python3.9/concurrent/futures/_base.py", line 445, in result
    return self.__get_result()
  File "/data/g0017139/.envs/ClusterEnv/lib/python3.9/concurrent/futures/_base.py", line 390, in __get_result
    raise self._exception
concurrent.futures.process.BrokenProcessPool: A process in the process pool was terminated abruptly while the future was running or pending.
